Workbook

Sheet All_Location_Details
A1: PDS Name | B1: Item Name | C1: Indent No | D1: Location Name | F1: Priority | G1: General Standard | H1: MOC Standard | I1: MOC Grade | J1: Item Size | K1: Item Unit | L1: Item Type | M1: Item Subtype | N1: Dimensional Standard | O1: MOC Schedule/Class | P1: Item Finish | Q1: Location Details Auto Number | R1: Wastage | S1: Process Name | T1: Added Time | U1: Modified Time | V1: ID
A2: PDS - Distillation Column | B2: Plate | C2: 1A10110111 | D2: Dishend | F2: 1A | G2: US | H2: ASTM A240 | I2: Gr 304 | J2: 1500 | K2: mm | L2: Hot Rolled | P2: Mill Finish | Q2: LD/1 | R2: 21 | S2: Pressing | T2: 45015.533 | U2: 45610.646 | V2: 216666000000398383
A3: PDS - Distillation Column | B3: Plate | C3: 1A10110211 | D3: Cone | F3: 1A | G3: US | H3: ASTM A240 | I3: Gr 304 | J3: 1500 | K3: mm | L3: Hot Rolled | P3: Mill Finish | Q3: LD/4 | R3: 15 | S3: Rolling,Knuckling | T3: 45015.533 | U3: 45610.646 | V3: 216666000000398386
A4: PDS - Distillation Column | B4: Plate | C4: 1A10110411 | D4: Shell Plate | F4: 1A | G4: US | H4: ASTM A240 | I4: Gr 304 | J4: 1500 | K4: mm | L4: Hot Rolled | P4: Mill Finish | Q4: LD/17 | R4: 3 | T4: 45015.533 | U4: 45428.537 | V4: 216666000000398399
A5: PDS - Distillation Column | B5: Plate | C5: 1A10110911 | D5: Body Flange Liner | F5: 1A | G5: US | H5: ASTM A240 | I5: Gr 304 | J5: 1500 | K5: mm | L5: Hot Rolled | P5: Mill Finish | Q5: LD/11 | R5: 10 | T5: 45015.533 | U5: 45428.708 | V5: 216666000000398393
A6: PDS - Distillation Column | B6: Plate | C6: 1A10112111 | D6: Nozzle Liner | F6: 1A | G6: US | H6: ASTM A240 | I6: Gr 304 | J6: 1500 | K6: mm | L6: Hot Rolled | P6: Mill Finish | Q6: LD/14 | R6: 10 | T6: 45015.533 | U6: 45428.708 | V6: 216666000000398396
A7: PDS - Distillation Column | B7: Plate | C7: 1A10112311 | D7: Nozzle Gusset | F7: 3C | G7: US | H7: ASTM A240 | I7: Gr 304 | J7: 1500 | K7: mm | L7: Hot Rolled | P7: Mill Finish | Q7: LD/20 | R7: 10 | T7: 45015.533 | U7: 45428.718 | V7: 216666000000398402
A8: PDS - Distillation Column | B8: Pipe | C8: 1A10112611 | D8: Leg Support | F8: 1A | G8: US | H8: ASTM A312 | I8: Gr 304 | K8: NB | L8: ERW | N8: ASME B36.10M | O8: Sch 10S | Q8: LD/414 | T8: 45469.53 | U8: 45470.708 | V8: 216666000000950123
A9: PDS - Distillation Column | B9: Plate | C9: 1A10112711 | D9: Skirt Support | F9: 2A | G9: US | H9: ASTM A240 | I9: Gr 304 | J9: 1500 | K9: mm | L9: Hot Rolled | P9: Mill Finish | Q9: LD/25 | R9: 3 | T9: 45015.533 | U9: 45428.709 | V9: 216666000000398407
A10: PDS - Distillation Column | B10: Plate | C10: 1A10112811 | D10: Base Plate | F10: 1B | G10: US | H10: ASTM A240 | I10: Gr 304 | J10: 1500 | K10: mm | L10: Hot Rolled | P10: Mill Finish | Q10: LD/28 | R10: 25 | T10: 45015.533 | U10: 45492.723 | V10: 216666000000398410
A11: PDS - Distillation Column | B11: Plate | C11: 1A10112911 | D11: Gusset Plate | F11: 2A | G11: US | H11: ASTM A240 | I11: Gr 304 | J11: 1500 | K11: mm | L11: Hot Rolled | P11: Mill Finish | Q11: LD/31 | R11: 10 | T11: 45015.533 | U11: 45428.718 | V11: 216666000000398413
A12: PDS - Distillation Column | B12: Plate | C12: 1A10113111 | D12: Name Plate Bracket | F12: 2C | G12: US | H12: ASTM A240 | I12: Gr 304 | J12: 1500 | K12: mm | L12: Hot Rolled | P12: Mill Finish | Q12: LD/34 | R12: 3 | T12: 45015.533 | U12: 45428.721 | V12: 216666000000398416
A13: PDS - Distillation Column | B13: Plate | C13: 1A10113311 | D13: Logo Plate Bracket | F13: 2C | G13: US | H13: ASTM A240 | I13: Gr 304 | J13: 1500 | K13: mm | L13: Hot Rolled | P13: Mill Finish | Q13: LD/37 | R13: 3 | T13: 45015.533 | U13: 45428.721 | V13: 216666000000398419
A14: PDS - Distillation Column | B14: Plate | C14: 1A10113411 | D14: Lifting Lug | F14: 2A | G14: US | H14: ASTM A240 | I14: Gr 304 | J14: 1500 | K14: mm | L14: Hot Rolled | P14: Mill Finish | Q14: LD/40 | R14: 10 | T14: 45015.533 | U14: 45428.719 | V14: 216666000000398422
A15: PDS - Distillation Column | B15: Plate | C15: 1A10113611 | D15: Trunion Closer Plate | F15: 1B | G15: US | H15: ASTM A240 | I15: Gr 304 | J15: 1500 | K15: mm | L15: Hot Rolled | P15: Mill Finish | Q15: LD/43 | R15: 21 | T15: 45015.533 | U15: 45428.71 | V15: 216666000000398425
A16: PDS - Distillation Column | B16: Plate | C16: 1A10114011 | D16: Vortex Breaker | F16: 3B | G16: US | H16: ASTM A240 | I16: Gr 304 | J16: 1500 | K16: mm | L16: Hot Rolled | P16: Mill Finish | Q16: LD/46 | R16: 10 | T16: 45015.533 | U16: 45428.721 | V16: 216666000000398428
A17: PDS - Distillation Column | B17: Plate | C17: 1A10114511 | D17: Tray | F17: 1A | G17: US | H17: ASTM A240 | I17: Gr 304 | J17: 1500 | K17: mm | L17: Hot Rolled | P17: Mill Finish | Q17: LD/55 | R17: 10 | T17: 45015.533 | U17: 45492.507 | V17: 216666000000398437
A18: PDS - Distillation Column | B18: Plate | C18: 1A10114711 | D18: Tray Support Clits | F18: 1A | G18: US | H18: ASTM A240 | I18: Gr 304 | J18: 1500 | K18: mm | L18: Hot Rolled | P18: Mill Finish | Q18: LD/56 | R18: 5 | T18: 45015.533 | U18: 45428.715 | V18: 216666000000398438
A19: PDS - Distillation Column | B19: Plate | C19: 1A10114811 | D19: Junction Plate | F19: 3C | G19: US | H19: ASTM A240 | I19: Gr 304 | J19: 1500 | K19: mm | L19: Hot Rolled | P19: Mill Finish | Q19: LD/58 | R19: 3 | T19: 45015.533 | U19: 45428.715 | V19: 216666000000398440
A20: PDS - Distillation Column | B20: Plate | C20: 1A10114911 | D20: Compression Plate | F20: 2A | G20: US | H20: ASTM A240 | I20: Gr 304 | J20: 1500 | K20: mm | L20: Hot Rolled | P20: Mill Finish | Q20: LD/59 | R20: 25 | T20: 45015.533 | U20: 45428.715 | V20: 216666000000398441
... A40: PDS - Distillation Column | B40: Plate | C40: 1A10122511 | D40: Internal Gusset | F40: 1A | G40: US | H40: ASTM A240 | I40: Gr 304 | J40: 1500 | K40: mm | L40: Hot Rolled | P40: Mill Finish | Q40: LD/102 | R40: 10 | T40: 45015.533 | U40: 45428.718 | V40: 216666000000398484
A41: PDS - Distillation Column | B41: Plate | C41: 1A10127511 | D41: Support Ring | F41: 1A | G41: US | H41: ASTM A240 | I41: Gr 304 | J41: 1500 | K41: mm | L41: Hot Rolled | P41: Mill Finish | Q41: LD/449 | T41: 45474.742 | U41: 45483.535 | V41: 216666000000968007
A42: PDS - Distillation Column | B42: Plate | C42: 1A10129311 | D42: Closer Plate | F42: 1A | G42: US | H42: ASTM A240 | I42: Gr 304 | J42: 1500 | K42: mm | L42: Hot Rolled | P42: Mill Finish | Q42: LD/415 | R42: 15 | T42: 45469.663 | U42: 45470.708 | V42: 216666000000952003
A43: PDS - Distillation Column | B43: Flat - Plate | C43: 1A10210311 | D43: External Stiffner | F43: 1B | G43: US | H43: ASTM A240 | I43: Gr 304 | J43: 50 | K43: mm | L43: Hot Rolled | P43: Mill Finish | Q43: LD/103 | R43: 10 | T43: 45015.533 | U43: 45428.717 | V43: 216666000000398485
A44: PDS - Distillation Column | B44: Flat - Plate | C44: 1A10210611 | D44: Body Flange Flat | F44: 1B | G44: US | H44: ASTM A240 | I44: Gr 304 | J44: 50 | K44: mm | L44: Hot Rolled | P44: Mill Finish | Q44: LD/106 | T44: 45015.533 | U44: 45423.684 | V44: 216666000000398488
A45: PDS - Distillation Column | B45: Flat - Plate | C45: 1A10214611 | D45: Tray Support Ring | F45: 1A | G45: US | H45: ASTM A240 | I45: Gr 304 | J45: 50 | K45: mm | L45: Hot Rolled | P45: Mill Finish | Q45: LD/108 | R45: 6 | T45: 45015.533 | U45: 45496.694 | V45: 216666000000398490
A46: PDS - Distillation Column | B46: Flat - Plate | C46: 1A10218411 | D46: Backing Strip | F46: 3B | G46: US | H46: ASTM A240 | I46: Gr 304 | J46: 50 | K46: mm | L46: Hot Rolled | P46: Mill Finish | Q46: LD/109 | R46: 5 | T46: 45015.533 | U46: 45428.717 | V46: 216666000000398491
A47: PDS - Distillation Column | B47: Pipe | C47: 1A10311611 | D47: Nozzle Pipe | F47: 3A | G47: US | H47: ASTM A312 | I47: Gr 304 | K47: NB | L47: ERW | Q47: LD/112 | T47: 45015.539 | U47: 45423.696 | V47: 216666000000398583
A48: PDS - Distillation Column | B48: Pipe | C48: 1A10313511 | D48: Trunion Pipe | F48: 3A | G48: US | H48: ASTM A312 | I48: Gr 304 | K48: NB | L48: ERW | Q48: LD/116 | T48: 45015.539 | U48: 45423.696 | V48: 216666000000398584
A49: PDS - Distillation Column | B49: Pipe | C49: 1A10313811 | D49: Vent Hole | F49: 3B | G49: US | H49: ASTM A312 | I49: Gr 304 | K49: NB | L49: ERW | Q49: LD/119 | T49: 45015.539 | U49: 45423.697 | V49: 216666000000398585
A50: PDS - Distillation Column | B50: Pipe | C50: 1A10315011 | D50: Riser | F50: 1B | G50: India | H50: IS 1239 | I50: Gr A | K50: NB | L50: ERW | N50: IS 1239 | O50: Class C | Q50: LD/394 | T50: 45441.448 | U50: 45441.448 | V50: 216666000000862075
A51: PDS - Distillation Column | B51: Pipe | C51: 1A10320011 | D51: SG - LG Pipe | F51: 2C | G51: US | H51: ASTM A312 | I51: Gr 304 | K51: NB | L51: ERW | Q51: LD/129 | T51: 45015.539 | U51: 45423.697 | V51: 216666000000398586
A52: PDS - Distillation Column | B52: Pipe | C52: 1A10320911 | D52: Distance Piece For Bend | F52: 2A | G52: US | H52: ASTM A312 | I52: Gr 304 | J52: 32 | K52: NB | L52: ERW | Q52: LD/136 | T52: 45015.533 | U52: 45545.635 | V52: 216666000000398512
A53: PDS - Distillation Column | B53: Pipe | C53: 1A10321011 | D53: Downcomer Pipe | F53: 3C | G53: US | H53: ASTM A312 | I53: Gr 304 | K53: NB | L53: ERW | Q53: LD/132 | T53: 45015.539 | U53: 45423.698 | V53: 216666000000398587
A54: PDS - Distillation Column | B54: Pipe | C54: 1A10331611 | D54: Vapour Pipe | F54: 2A | G54: India | H54: IS 1239 | I54: Gr A | J54: 10 | K54: NB | L54: ERW | N54: IS 1239 | O54: Class C | Q54: LD/392 | T54: 45439.728 | U54: 45439.728 | V54: 216666000000854817
A55: PDS - Distillation Column | B55: Pipe | C55: 1A10331711 | D55: Vapour Bend | F55: 2A | G55: India | H55: IS 1239 | I55: Gr A | K55: NB | L55: ERW | N55: IS 1239 | O55: Class C | Q55: LD/393 | T55: 45439.729 | U55: 45439.729 | V55: 216666000000854829
A56: PDS - Distillation Column | B56: Pipe | C56: 1A10334411 | D56: Packing Pipe | F56: 2B | G56: US | H56: ASTM A312 | I56: Gr 304 | J56: 150 | K56: NB | L56: ERW | N56: ASME B36.10M | O56: Sch 10S | Q56: LD/493 | T56: 45528.533 | U56: 45528.535 | V56: 216666000001386003
A57: PDS - Distillation Column | B57: Elbow | C57: 1A10412011 | D57: Nozzle Elbow | F57: 2C | G57: US | H57: ASTM A403 | I57: WP 304 | K57: NB | Q57: LD/133 | T57: 45015.533 | U57: 45423.7 | V57: 216666000000398509
A58: PDS - Distillation Column | B58: Flanges | C58: 1A10611811 | D58: Nozzle Flange | F58: 2C | G58: India | H58: IS 2062 | I58: Gr B | K58: NB | L58: LJFF | N58: IS 6392 | O58: #150 | Q58: LD/138 | T58: 45015.533 | U58: 45423.701 | V58: 216666000000398514
A59: PDS - Distillation Column | B59: Stubend | C59: 1A10711711 | D59: Nozzle Stubend | F59: 2C | G59: US | H59: ASTM A403 | I59: WP 304 | K59: NB | Q59: LD/143 | T59: 45015.533 | U59: 45423.704 | V59: 216666000000398519
...

Sheet Condenser+Cooler (1 Pass)
A2: PDS - Shell & Tube HE | B2: Plate | C2: 1A10110412 | D2: Shell Plate | F2: 1A | G2: US | H2: ASTM A240 | I2: Gr 304 | J2: 1500 | K2: mm | L2: Hot Rolled | P2: Mill Finish | Q2: LD/7 | R2: 3 | T2: 45015.533 | U2: 45428.537 | V2: 216666000000398389
A3: PDS - Shell & Tube HE | B3: Plate | C3: 1A10110112 | D3: Dishend | F3: 1A | G3: US | H3: ASTM A240 | I3: Gr 304 | J3: 1500 | K3: mm | L3: Hot Rolled | P3: Mill Finish | Q3: LD/2 | R3: 21 | T3: 45015.533 | U3: 45428.534 | V3: 216666000000398384
A4: PDS - Shell & Tube HE | B4: Plate | C4: 1A10114312 | D4: Bonnet Shell | F4: 3A | G4: US | H4: ASTM A240 | I4: Gr 304 | J4: 1500 | K4: mm | L4: Hot Rolled | P4: Mill Finish | Q4: LD/51 | R4: 3 | T4: 45015.533 | U4: 45545.703 | V4: 216666000000398433
A5: PDS - Shell & Tube HE | B5: Plate | C5: 1A10114312 | D5: Bonnet Shell | F5: 3A | G5: US | H5: ASTM A240 | I5: Gr 304 | J5: 1500 | K5: mm | L5: Hot Rolled | P5: Mill Finish | Q5: LD/51 | R5: 3 | T5: 45015.533 | U5: 45545.703 | V5: 216666000000398433
A6: PDS - Shell & Tube HE | B6: Tube | C6: 1A12316512 | D6: Tubes | F6: 1A | G6: US | H6: ASTM A249 | I6: Gr 304 | Q6: LD/189 | T6: 45015.533 | U6: 45423.743 | V6: 216666000000398565
A7: PDS - Shell & Tube HE | B7: Tubesheet | C7: 1A12215912 | D7: Tubesheet | F7: 1B | G7: US | H7: ASTM A240 | I7: Gr 304 | Q7: LD/187 | T7: 45015.533 | U7: 45423.742 | V7: 216666000000398563
A8: PDS - Shell & Tube HE | B8: Plate | C8: 1A10116012 | D8: Baffle Plate | F8: 1A | G8: US | H8: ASTM A240 | I8: Gr 304 | J8: 1500 | K8: mm | L8: Hot Rolled | P8: Mill Finish | Q8: LD/65 | R8: 22 | T8: 45015.533 | U8: 45436.588 | V8: 216666000000398447
A9: PDS - Shell & Tube HE | B9: Solid Bar | C9: 1A12516212 | D9: Tie Rod | F9: 1C | G9: US | H9: AISI 304 | Q9: LD/192 | T9: 45015.533 | U9: 45423.744 | V9: 216666000000398568
A10: PDS - Shell & Tube HE | B10: Tube | C10: 1A12316112 | D10: Spacer Tube | F10: 1C | G10: US | H10: ASTM A249 | I10: Gr 304 | Q10: LD/188 | T10: 45015.533 | U10: 45423.742 | V10: 216666000000398564
A11: PDS - Shell & Tube HE | B11: Nut | C11: 1A11219712 | D11: Hex Nut | F11: 2C | G11: US | H11: AISI 304 | Q11: LD/157 | T11: 45015.533 | U11: 45423.739 | V11: 216666000000398533
A12: PDS - Shell & Tube HE | B12: Nut | C12: 1A11216712 | D12: Lock Nut | F12: 2C | G12: US | H12: AISI 304 | Q12: LD/156 | T12: 45015.533 | U12: 45423.739 | V12: 216666000000398532
A13: PDS - Shell & Tube HE | B13: Plate | C13: 1A10110912 | D13: Body Flange Liner | F13: 1A | G13: US | H13: ASTM A240 | I13: Gr 304 | J13: 1500 | K13: mm | L13: Hot Rolled | P13: Mill Finish | Q13: LD/12 | R13: 10 | T13: 45015.533 | U13: 45428.708 | V13: 216666000000398394
A14: PDS - Shell & Tube HE | B14: Plate | C14: 1A10110612 | D14: Body Flange | F14: 1B | G14: India | H14: IS 2062 | I14: Gr B | J14: 1500 | K14: mm | L14: Hot Rolled | P14: Mill Finish | Q14: LD/477 | T14: 45504.6 | U14: 45505.742 | V14: 216666000001274003
A15: PDS - Shell & Tube HE | B15: Gasket | C15: 1A10810812 | D15: Gasket - Body Flange | F15: 2C | L15: NACF | Q15: LD/147 | T15: 45015.533 | U15: 45015.533 | V15: 216666000000398523
A16: PDS - Shell & Tube HE | B16: Nut, Bolt & Washer | C16: 1A11410712 | D16: Nut Bolt & Washer - Body Flange | F16: 3A | G16: US | H16: SA 193 | I16: B7/2H | Q16: LD/160 | T16: 45015.533 | U16: 45015.533 | V16: 216666000000398536
A17: PDS - Shell & Tube HE | B17: Plate | C17: 1A10118212 | D17: Pad Plates For Lifting Lug | F17: 1A | G17: US | H17: ASTM A240 | I17: Gr 304 | J17: 1500 | K17: mm | L17: Hot Rolled | P17: Mill Finish | Q17: LD/72 | R17: 3 | T17: 45015.533 | U17: 45428.723 | V17: 216666000000398454
A18: PDS - Shell & Tube HE | B18: Plate | C18: 1A10113412 | D18: Lifting Lug | F18: 2A | G18: India | H18: IS 2062 | I18: Gr A | J18: 1500 | K18: mm | L18: Hot Rolled | P18: Mill Finish | Q18: LD/41 | R18: 10 | T18: 45015.533 | U18: 45428.719 | V18: 216666000000398423
A19: PDS - Shell & Tube HE | B19: Plate | C19: 1A10113112 | D19: Name Plate Bracket | F19: 2C | G19: US | H19: ASTM A240 | I19: Gr 304 | J19: 1500 | K19: mm | L19: Hot Rolled | P19: Mill Finish | Q19: LD/35 | R19: 3 | T19: 45015.533 | U19: 45428.721 | V19: 216666000000398417
A20: PDS - Shell & Tube HE | B20: Gasket | C20: 1A10819312 | D20: C - Type Gasket | F20: 2C | L20: NACF | Q20: LD/154 | T20: 45015.533 | U20: 45015.533 | V20: 216666000000398530
A21: PDS - Shell & Tube HE | B21: Plate | C21: 1A10119012 | D21: Pad Plate For Saddle support | F21: 1A | G21: India | H21: IS 2062 | I21: Gr A | J21: 1500 | K21: mm | L21: Hot Rolled | P21: Mill Finish | Q21: LD/81 | R21: 3 | T21: 45015.533 | U21: 45428.722 | V21: 216666000000398463
A22: PDS - Shell & Tube HE | B22: Plate | C22: 1A10112812 | D22: Base Plate | F22: 1B | G22: India | H22: IS 2062 | I22: Gr A | J22: 1500 | K22: mm | L22: Hot Rolled | P22: Mill Finish | Q22: LD/29 | R22: 15 | T22: 45015.533 | U22: 45428.72 | V22: 216666000000398411
A23: PDS - Shell & Tube HE | B23: Plate | C23: 1A10114412 | D23: Saddle Plate | F23: 2A | G23: India | H23: IS 2062 | I23: Gr A | J23: 1500 | K23: mm | L23: Hot Rolled | P23: Mill Finish | Q23: LD/53 | R23: 5 | T23: 45015.533 | U23: 45428.722 | V23: 216666000000398435
A24: PDS - Shell & Tube HE | B24: Plate | C24: 1A10114412 | D24: Saddle Plate | F24: 2A | G24: India | H24: IS 2062 | I24: Gr A | J24: 1500 | K24: mm | L24: Hot Rolled | P24: Mill Finish | Q24: LD/53 | R24: 5 | T24: 45015.533 | U24: 45428.722 | V24: 216666000000398435
A25: PDS - Shell & Tube HE | B25: Plate | C25: 1A10119212 | D25: Rib Plate | F25: 2A | G25: US | H25: ASTM A240 | I25: Gr 304 | J25: 1500 | K25: mm | L25: Hot Rolled | P25: Mill Finish | Q25: LD/86 | R25: 10 | T25: 45015.533 | U25: 45441.49 | V25: 216666000000398468
A26: PDS - Shell & Tube HE | B26: Plate | C26: 1A10119212 | D26: Rib Plate | F26: 2A | G26: US | H26: ASTM A240 | I26: Gr 304 | J26: 1500 | K26: mm | L26: Hot Rolled | P26: Mill Finish | Q26: LD/86 | R26: 10 | T26: 45015.533 | U26: 45441.49 | V26: 216666000000398468
A27: PDS - Shell & Tube HE | B27: Earthing Boss | C27: 1A12913712 | D27: Earthing Boss | F27: 3C | G27: India | H27: IS 2062 | I27: Gr B | J27: 40 x 40 x M12 | K27: mm | Q27: LD/197 | T27: 45015.533 | U27: 45427.426 | V27: 216666000000398573

Sheet Condenser (2 & 4 Pass)
G2: HTA | H2: 100 | I2: Tube Qty | J2: =P2*J3 -> 420 | P2: =ROUNDUP(Q2/J3,0) -> 105 | Q2: =H2/(((H3/1000)*PI())*(H4/1000)) -> 417.72951 | S2: HTA/(((Tube OD./1000)*pi)*(Tube Length/1000))
G3: TUBE OD. | H3: 25.4 | I3: No Of Pass | J3: 4
G4: Tube Length | H4: 3000 | I4: Shell ID. | J4: =ROUNDUP(((((J2^0.5)+1.25*(J3^0.5))*1.25*1.05*H3)+25)/10,0)*10 -> 800
G5: Tube THK | H5: 1.6 | I5: R.S. Bonnet Shell | J5: 300
G6: Baffle Qty | H6: 5 | I6: F.S. Bonnet Shell | J6: 200
C11: Location Name | D11: Item Name | E11: Priority | F11: General Standard | G11: MOC Standard | H11: MOC Grade | I11: Item Size | J11: Item Unit | K11: Item Type | L11: Item Subtype | M11: Dimensional Standard | N11: MOC Schedule/Class | O11: Item Finish | P11: Special Specs | Q11: Thickness | R11: Other Value | S11: Quantity | T11: Remaining Qty | U11: Finish Length | V11: Raw Length | W11: Remaining Length | X11: Finish Weight
A12: PDS - Shell & Tube HE | B12: 1A10110412 | C12: Shell Plate | D12: Plate | E12: 1A | F12: US | G12: ASTM A240 | H12: Gr 304 | I12: 1500 | J12: mm | K12: Hot Rolled | O12: Mill Finish | P12: =(J4+Q12)*PI() -> 2528.9821 | Q12: =VLOOKUP(J4,'Heat Exchanger Data'!C3:W227,2,0) -> 5 | S12: 1 | U12: =(H4-Q17-Q17)+8 -> 2948 | X12: =P12*U12*Q12*8*10^-6*S12 -> 298.21757 | Z12: LD/7 | AB12: 45015.533 | AC12: 45428.537 | AD12: 216666000000398389
A13: PDS - Shell & Tube HE | B13: 1A10110112 | C13: Dishend | D13: Plate | E13: 1A | F13: US | G13: ASTM A240 | H13: Gr 304 | I13: 1500 | J13: mm | K13: Hot Rolled | O13: Mill Finish | P13: =J4*1.1+50 -> 930 | Q13: =VLOOKUP(J4,'Heat Exchanger Data'!C4:W228,4,0) -> 5 | S13: 2 | X13: =0.7854*(P13*P13)*Q13*8*10^-6*S13 -> 54.343397 | Z13: LD/2 | AB13: 45015.533 | AC13: 45428.534 | AD13: 216666000000398384
A14: PDS - Shell & Tube HE | B14: 1A10114312 | C14: Bonnet Shell | D14: Plate | E14: 3A | F14: US | G14: ASTM A240 | H14: Gr 304 | I14: 1500 | J14: mm | K14: Hot Rolled | O14: Mill Finish | P14: =(J4+Q14)*PI() -> 2528.9821 | Q14: =Q12 -> 5 | S14: 1 | U14: =J5 -> 300 | X14: =P14*U14*Q14*8*10^-6*S14 -> 30.347785 | Z14: LD/51 | AB14: 45015.533 | AC14: 45545.703 | AD14: 216666000000398433
A15: PDS - Shell & Tube HE | B15: 1A10114312 | C15: Bonnet Shell | D15: Plate | E15: 3A | F15: US | G15: ASTM A240 | H15: Gr 304 | I15: 1500 | J15: mm | K15: Hot Rolled | O15: Mill Finish | P15: =(J4+Q15)*PI() -> 2528.9821 | Q15: =Q12 -> 5 | S15: 1 | U15: =J6 -> 200 | X15: =P15*U15*Q15*8*10^-6*S15 -> 20.231857 | Z15: LD/51 | AB15: 45015.533 | AC15: 45545.703 | AD15: 216666000000398433
A16: PDS - Shell & Tube HE | B16: 1A12316512 | C16: Tubes | D16: Tube | E16: 1A | F16: US | G16: ASTM A249 | H16: Gr 304 | I16: =H3 -> 25.4 | J16: mm | K16: Circular | Q16: =H5 -> 1.6 | S16: =J2 -> 420 | V16: =H4 -> 3000 | X16: =((I16-Q16)*PI())*V16*Q16*8*10^-6*S16 -> 1205.889 | Z16: LD/189 | AB16: 45015.533 | AC16: 45423.743 | AD16: 216666000000398565
A17: PDS - Shell & Tube HE | B17: 1A12215912 | C17: Tubesheet | D17: Tubesheet | E17: 1B | F17: US | G17: ASTM A240 | H17: Gr 304 | J17: mm | K17: Circular | P17: =VLOOKUP(J4,'Heat Exchanger Data'!C3:W227,15,0)+5 -> 817 | Q17: =VLOOKUP(J4,'Heat Exchanger Data'!C3:W227,5,0)+3 -> 30 | S17: 2 | X17: =0.7854*(P17*P17)*Q17*8*10^-6*S17 -> 251.63801 | Z17: LD/187 | AB17: 45015.533 | AC17: 45423.742 | AD17: 216666000000398563
A18: PDS - Shell & Tube HE | B18: 1A10116012 | C18: Baffle Plate | D18: Plate | E18: 1A | F18: US | G18: ASTM A240 | H18: Gr 304 | I18: 1500 | J18: mm | K18: Hot Rolled | O18: Mill Finish | P18: =J4-5 -> 795 | Q18: =VLOOKUP(J4,'Heat Exchanger Data'!C3:W227,7,0) -> 36 | S18: =H6 -> 5 | X18: =0.7854*(P18*P18)*Q18*8*10^-6*S18 -> 714.80511 | Z18: LD/65 | AB18: 45015.533 | AC18: 45436.588 | AD18: 216666000000398447
A19: PDS - Shell & Tube HE | B19: 1A12516212 | C19: Tie Rod | D19: Solid Bar | E19: 1C | F19: US | G19: AISI 304 | I19: =VLOOKUP(J4,'Heat Exchanger Data'!C3:W227,17,0) -> 925 | J19: mm | K19: Round Bar | Z19: LD/192 | AB19: 45015.533 | AC19: 45423.744 | AD19: 216666000000398568
A20: PDS - Shell & Tube HE | B20: 1A12316112 | C20: Spacer Tube | D20: Pipe | E20: 1C | F20: US | G20: ASTM A249 | H20: TP 304 | I20: =VLOOKUP(J4,'Heat Exchanger Data'!C4:X228,19,0) -> 852 | J20: NB | K20: ERW | M20: ASME B36.10M | N20: Sch 5S | Z20: LD/188 | AB20: 45015.533 | AC20: 45423.742 | AD20: 216666000000398564
A21: PDS - Shell & Tube HE | B21: 1A11219712 | C21: Hex Nut | D21: Nut | E21: 2C | F21: US | G21: AISI 304 | I21: =I19 -> 925 | J21: mm | K21: Hex Nut | S21: =VLOOKUP(J4,'Heat Exchanger Data'!C3:W227,18,0) -> 930 | Z21: LD/157 | AB21: 45015.533 | AC21: 45423.739 | AD21: 216666000000398533
A22: PDS - Shell & Tube HE | B22: 1A11216712 | C22: Lock Nut | D22: Nut | E22: 2C | F22: US | G22: AISI 304 | I22: =I19 -> 925 | J22: mm | K22: Lock Nut | S22: =S21 -> 930 | Z22: LD/156 | AB22: 45015.533 | AC22: 45423.739 | AD22: 216666000000398532
A23: PDS - Shell & Tube HE | B23: 1A10110912 | C23: Body Flange Liner | D23: Plate | E23: 1A | F23: US | G23: ASTM A240 | H23: Gr 304 | I23: 1500 | J23: mm | K23: Hot Rolled | O23: Mill Finish | P23: =VLOOKUP(J4,'Heat Exchanger Data'!C3:W227,16,0) -> 880 | Q23: 6 | R23: =J4 -> 800 | S23: 2 | X23: =0.7854*(P23*P23-R23*R23)*Q23*8*10^-6*S23 -> 10.133545 | Z23: LD/12 | AB23: 45015.533 | AC23: 45428.708 | AD23: 216666000000398394
A24: PDS - Shell & Tube HE | B24: 1A10110612 | C24: Body Flange | D24: Flat - Plate | E24: 1B | F24: India | G24: IS 2062 | H24: Gr B | J24: mm | K24: Hot Rolled | O24: Mill Finish | Q24: =VLOOKUP(J4,'Heat Exchanger Data'!C3:W227,6,0)+4 -> 34 | S24: 2 | V24: =P17*PI()+300 -> 2866.6812 | X24: =P24*V24*Q24*7.85*10^-6*S24 -> 0 | Z24: LD/477 | AB24: 45504.6 | AC24: 45505.742 | AD24: 216666000001274003
A25: PDS - Shell & Tube HE | B25: 1A10810812 | C25: Gasket - Body Flange | D25: Gasket | E25: 2C | K25: NACF | P25: =P23 -> 880 | Q25: 5 | R25: =R23 -> 800 | S25: =S23 -> 2 | Z25: LD/147 | AB25: 45015.533 | AC25: 45015.533 | AD25: 216666000000398523
A26: PDS - Shell & Tube HE | B26: 1A11410712 | C26: Nut Bolt & Washer - Body Flange | D26: Nut, Bolt & Washer | E26: 3A | F26: US | G26: SA 193 | H26: B7/2H | I26: =VLOOKUP(J4,'Heat Exchanger Data'!C3:W227,9,0) -> 8 | J26: mm | K26: Hexagonal Type | S26: =VLOOKUP(J4,'Heat Exchanger Data'!C3:W227,11,0) -> M16 | V26: =VLOOKUP(J4,'Heat Exchanger Data'!C3:W227,10,0) -> 6 | Z26: LD/160 | AB26: 45015.533 | AC26: 45015.533 | AD26: 216666000000398536
A27: PDS - Shell & Tube HE | B27: 1A10118212 | C27: Pad Plates For Lifting Lug | D27: Plate | E27: 1A | F27: US | G27: ASTM A240 | H27: Gr 304 | I27: 1500 | J27: mm | K27: Hot Rolled | O27: Mill Finish | P27: 75 | Q27: =Q12 -> 5 | S27: 2 | U27: 200 | X27: =P27*U27*Q27*8*10^-6*S27 -> 1.2 | Z27: LD/72 | AB27: 45015.533 | AC27: 45428.723 | AD27: 216666000000398454
A28: PDS - Shell & Tube HE | B28: 1A10113412 | C28: Lifting Lug | D28: Plate | E28: 2A | F28: India | G28: IS 2062 | H28: Gr A | I28: 1500 | J28: mm | K28: Hot Rolled | O28: Mill Finish | P28: 130 | Q28: 12 | S28: 2 | U28: 150 | X28: =P28*U28*Q28*8*10^-6*S28 -> 3.744 | Z28: LD/41 | AB28: 45015.533 | AC28: 45428.719 | AD28: 216666000000398423
A29: PDS - Shell & Tube HE | B29: 1A10113112 | C29: Name Plate Bracket | D29: Plate | E29: 2C | F29: US | G29: ASTM A240 | H29: Gr 304 | I29: 1500 | J29: mm | K29: Hot Rolled | O29: Mill Finish | P29: 145 | Q29: 3 | S29: 1 | U29: 270 | X29: =P29*U29*Q29*8*10^-6*S29 -> 0.9396 | Z29: LD/35 | AB29: 45015.533 | AC29: 45428.721 | AD29: 216666000000398417
A30: PDS - Shell & Tube HE | B30: 1A10117112 | C30: Partition Plate | D30: Plate | E30: 1A | F30: US | G30: ASTM A240 | H30: Gr 304 | I30: 1500 | J30: mm | K30: Hot Rolled | O30: Mill Finish | P30: =J4-4 -> 796 | Q30: =VLOOKUP(J4,'Heat Exchanger Data'!C3:W227,7,0) -> 36 | S30: 1 | U30: =0.193*J4+J5 -> 454.4 | X30: =P30*U30*Q30*8*10^-6*S30 -> 104.17029 | Z30: LD/67 | AB30: 45015.533 | AC30: 45423.724 | AD30: 216666000000398449
A31: PDS - Shell & Tube HE | B31: 1A10117112 | C31: Partition Plate | D31: Plate | E31: 1A | F31: US | G31: ASTM A240 | H31: Gr 304 | I31: 1500 | J31: mm | K31: Hot Rolled | O31: Mill Finish | P31: =P30/2-2 -> 396 | Q31: =VLOOKUP(J4,'Heat Exchanger Data'!C3:W227,7,0) -> 36 | S31: 1 | U31: =U30 -> 454.4 | X31: =P31*U31*Q31*8*10^-6*S31 -> 51.823411 | Z31: LD/67 | AB31: 45015.533 | AC31: 45423.724 | AD31: 216666000000398449
A32: PDS - Shell & Tube HE | B32: 1A10117112 | C32: Partition Plate | D32: Plate | E32: 1A | F32: US | G32: ASTM A240 | H32: Gr 304 | I32: 1500 | J32: mm | K32: Hot Rolled | O32: Mill Finish | P32: =J4-4 -> 796 | Q32: =VLOOKUP(J4,'Heat Exchanger Data'!C3:W227,7,0) -> 36 | S32: 1 | U32: =0.193*J4+J6 -> 354.4 | X32: =P32*U32*Q32*8*10^-6*S32 -> 81.245491 | Z32: LD/67 | AB32: 45015.533 | AC32: 45423.724 | AD32: 216666000000398449
A33: PDS - Shell & Tube HE | B33: 1A10819312 | C33: C - Type Gasket | D33: Gasket | E33: 2C | K33: NACF | P33: 35 | Q33: 5 | S33: 1 | U33: =P30+P31+P32 -> 1988 | Z33: LD/154 | AB33: 45015.533 | AC33: 45015.533 | AD33: 216666000000398530
A34: PDS - Shell & Tube HE | B34: 1A10119012 | C34: Pad Plate For Saddle support | D34: Plate | E34: 1A | F34: India | G34: IS 2062 | H34: Gr A | I34: 1500 | J34: mm | K34: Hot Rolled | O34: Mill Finish | Z34: LD/81 | AB34: 45015.533 | AC34: 45428.722 | AD34: 216666000000398463
A35: PDS - Shell & Tube HE | B35: 1A10112812 | C35: Base Plate | D35: Plate | E35: 1B | F35: India | G35: IS 2062 | H35: Gr A | I35: 1500 | J35: mm | K35: Hot Rolled | O35: Mill Finish | Z35: LD/29 | AB35: 45015.533 | AC35: 45428.72 | AD35: 216666000000398411
A36: PDS - Shell & Tube HE | B36: 1A10114412 | C36: Saddle Plate | D36: Plate | E36: 2A | F36: India | G36: IS 2062 | H36: Gr A | I36: 1500 | J36: mm | K36: Hot Rolled | O36: Mill Finish | Z36: LD/53 | AB36: 45015.533 | AC36: 45428.722 | AD36: 216666000000398435
A37: PDS - Shell & Tube HE | B37: 1A10114412 | C37: Saddle Plate | D37: Plate | E37: 2A | F37: India | G37: IS 2062 | H37: Gr A | I37: 1500 | J37: mm | K37: Hot Rolled | O37: Mill Finish | Z37: LD/53 | AB37: 45015.533 | AC37: 45428.722 | AD37: 216666000000398435
A38: PDS - Shell & Tube HE | B38: 1A10119212 | C38: Rib Plate | D38: Plate | E38: 2A | F38: US | G38: ASTM A240 | H38: Gr 304 | I38: 1500 | J38: mm | K38: Hot Rolled | O38: Mill Finish | Z38: LD/86 | AB38: 45015.533 | AC38: 45441.49 | AD38: 216666000000398468
A39: PDS - Shell & Tube HE | B39: 1A10119212 | C39: Rib Plate | D39: Plate | E39: 2A | F39: US | G39: ASTM A240 | H39: Gr 304 | I39: 1500 | J39: mm | K39: Hot Rolled | O39: Mill Finish | Z39: LD/86 | AB39: 45015.533 | AC39: 45441.49 | AD39: 216666000000398468
A40: PDS - Shell & Tube HE | B40: 1A12913712 | C40: Earthing Boss | D40: Earthing Boss | E40: 3C | F40: India | G40: IS 2062 | I40: 40 x 40 x M12 | J40: mm | S40: 1 | Z40: LD/197 | AB40: 45015.533 | AC40: 45427.426 | AD40: 216666000000398573

Sheet Reboiler-NEN
A1: PDS Name | B1: Equipment Category | C1: Equipment Type | D1: Equipment Subtype | E1: Location Name | F1: Indent No | G1: Item Name | H1: Priority | I1: General Standard | J1: MOC Standard | K1: MOC Grade | L1: Item Size | M1: Item Unit | N1: Item Type | O1: Item Subtype | P1: Dimensional Standard | Q1: MOC Schedule/Class | R1: Item Finish
A2: PDS - Shell & Tube HE | B2: Shell & Tube Heat Exchanger | C2: Thermosyphon - Reboiler | D2: Single Pass | E2: Shell Plate | F2: 1A10110412 | G2: Plate | H2: 1A | I2: US | J2: ASTM A240 | K2: Gr 304 | L2: 1500 | M2: mm | N2: Hot Rolled | R2: Mill Finish
A3: PDS - Shell & Tube HE | B3: Shell & Tube Heat Exchanger | C3: Thermosyphon - Reboiler | D3: Single Pass | E3: Dishend | F3: 1A10110112 | G3: Plate | H3: 1A | I3: US | J3: ASTM A240 | K3: Gr 304 | L3: 1500 | M3: mm | N3: Hot Rolled | R3: Mill Finish
A4: PDS - Shell & Tube HE | B4: Shell & Tube Heat Exchanger | C4: Thermosyphon - Reboiler | D4: Single Pass | E4: Bonnet Shell | F4: 1A10114312 | G4: Plate | H4: 3A | I4: US | J4: ASTM A240 | K4: Gr 304 | L4: 1500 | M4: mm | N4: Hot Rolled | R4: Mill Finish
A5: PDS - Shell & Tube HE | B5: Shell & Tube Heat Exchanger | C5: Thermosyphon - Reboiler | D5: Single Pass | E5: Bonnet Shell | F5: 1A10114312 | G5: Plate | H5: 3A | I5: US | J5: ASTM A240 | K5: Gr 304 | L5: 1500 | M5: mm | N5: Hot Rolled | R5: Mill Finish
A6: PDS - Shell & Tube HE | B6: Shell & Tube Heat Exchanger | C6: Thermosyphon - Reboiler | D6: Single Pass | E6: Body Flange Flat | F6: 1A10210612 | G6: Flat - Plate | H6: 1B | I6: India | J6: IS 2062 | K6: Gr B | L6: 80 | M6: mm | N6: Hot Rolled | R6: Mill Finish
A7: PDS - Shell & Tube HE | B7: Shell & Tube Heat Exchanger | C7: Thermosyphon - Reboiler | D7: Single Pass | E7: Body Flange Liner | F7: 1A10110912 | G7: Plate | H7: 1A | I7: US | J7: ASTM A240 | K7: Gr 304 | L7: 1500 | M7: mm | N7: Hot Rolled | R7: Mill Finish
A8: PDS - Shell & Tube HE | B8: Shell & Tube Heat Exchanger | C8: Thermosyphon - Reboiler | D8: Single Pass | E8: Gasket - Body Flange | F8: 1A10810812 | G8: Gasket | H8: 2C | M8: mm | N8: NACF
A9: PDS - Shell & Tube HE | B9: Shell & Tube Heat Exchanger | C9: Thermosyphon - Reboiler | D9: Single Pass | E9: Tubesheet | F9: 1A12215912 | G9: Tubesheet | H9: 1B | I9: US | J9: ASTM A240 | K9: Gr 304 | M9: mm | N9: Circular
A10: PDS - Shell & Tube HE | B10: Shell & Tube Heat Exchanger | C10: Thermosyphon - Reboiler | D10: Single Pass | E10: Nut Bolt & Washer - Body Flange | F10: 1A11410712 | G10: Nut, Bolt & Washer | H10: 3A | I10: India | J10: IS 1367 | K10: Gr 8.8 | L10: M24 | M10: mm | N10: Hexagonal Type
A11: PDS - Shell & Tube HE | B11: Shell & Tube Heat Exchanger | C11: Thermosyphon - Reboiler | D11: Single Pass | E11: Tubes | F11: 1A12316512 | G11: Tube | H11: 1A | I11: US | J11: ASTM A249 | K11: Gr 304 | L11: 38.1 | M11: mm | N11: Circular | O11: ERW | P11: ASTM A450 | R11: Mill Finish
A12: PDS - Shell & Tube HE | B12: Shell & Tube Heat Exchanger | C12: Thermosyphon - Reboiler | D12: Single Pass | E12: Bonnet Shell | F12: 1A10114312 | G12: Plate | H12: 3A | I12: US | J12: ASTM A240 | K12: Gr 304 | L12: 1500 | M12: mm | N12: Hot Rolled | R12: Mill Finish
A13: PDS - Shell & Tube HE | B13: Shell & Tube Heat Exchanger | C13: Thermosyphon - Reboiler | D13: Single Pass | E13: Bonnet Shell | F13: 1A10114312 | G13: Plate | H13: 3A | I13: US | J13: ASTM A240 | K13: Gr 304 | L13: 1500 | M13: mm | N13: Hot Rolled | R13: Mill Finish
A14: PDS - Shell & Tube HE | B14: Shell & Tube Heat Exchanger | C14: Thermosyphon - Reboiler | D14: Single Pass | E14: Baffle Plate | F14: 1A10116012 | G14: Plate | H14: 1A | I14: US | J14: ASTM A240 | K14: Gr 304 | L14: 1500 | M14: mm | N14: Hot Rolled | R14: Mill Finish
A15: PDS - Shell & Tube HE | B15: Shell & Tube Heat Exchanger | C15: Thermosyphon - Reboiler | D15: Single Pass | E15: Tie Rod | F15: 1A12516212 | G15: Solid Bar | H15: 1C | I15: US | J15: AISI 304 | L15: 14 | M15: mm | N15: Round Bar
A16: PDS - Shell & Tube HE | B16: Shell & Tube Heat Exchanger | C16: Thermosyphon - Reboiler | D16: Single Pass | E16: Spacer Tube | F16: 1A12316112 | G16: Pipe | H16: 1C | I16: US | J16: AISI 304 | L16: 15 | M16: NB | N16: ERW | P16: ASME B36.10M | Q16: Sch 5S
A17: PDS - Shell & Tube HE | B17: Shell & Tube Heat Exchanger | C17: Thermosyphon - Reboiler | D17: Single Pass | E17: Hex Nut | F17: 1A11219712 | G17: Nut, Bolt & Washer | H17: 2C | I17: US | J17: AISI 304 | L17: M14 | M17: mm | N17: Hexagonal Type
A18: PDS - Shell & Tube HE | B18: Shell & Tube Heat Exchanger | C18: Thermosyphon - Reboiler | D18: Single Pass | E18: Lock Nut | F18: 1A11216712 | G18: Nut, Bolt & Washer | H18: 2C | I18: US | J18: AISI 304 | L18: M14 | M18: mm | N18: Hexagonal Type
A19: PDS - Shell & Tube HE | B19: Shell & Tube Heat Exchanger | C19: Thermosyphon - Reboiler | D19: Single Pass | E19: Pad Plate For Support Ring | F19: 1A10134812 | G19: Plate | H19: 2A | I19: US | J19: ASTM A240 | K19: Gr 304 | L19: 1500 | M19: mm | N19: Hot Rolled | R19: Mill Finish
A20: PDS - Shell & Tube HE | B20: Shell & Tube Heat Exchanger | C20: Thermosyphon - Reboiler | D20: Single Pass | E20: Gusset Plate | F20: 1A10112912 | G20: Plate | H20: 2A | I20: India | J20: IS 2062 | K20: Gr A | L20: 1500 | M20: mm | N20: Hot Rolled | R20: Mill Finish
A21: PDS - Shell & Tube HE | B21: Shell & Tube Heat Exchanger | C21: Thermosyphon - Reboiler | D21: Single Pass | E21: Bottom Support Ring | F21: 1A10120712 | G21: Plate | H21: 2A | I21: India | J21: IS 2062 | K21: Gr A | L21: 1500 | M21: mm | N21: Hot Rolled | R21: Mill Finish
A22: PDS - Shell & Tube HE | B22: Shell & Tube Heat Exchanger | C22: Thermosyphon - Reboiler | D22: Single Pass | E22: Top Support Ring | F22: 1A10120712 | G22: Plate | H22: 2A | I22: India | J22: IS 2062 | K22: Gr A | L22: 1500 | M22: mm | N22: Hot Rolled | R22: Mill Finish
A23: PDS - Shell & Tube HE | B23: Shell & Tube Heat Exchanger | C23: Thermosyphon - Reboiler | D23: Single Pass | E23: Earthing Boss | F23: 1A12913712 | G23: Earthing Boss | H23: 3C | I23: India | J23: IS 2062 | K23: Gr A | L23: 40 x 40 x M12 | M23: mm
A24: PDS - Shell & Tube HE | B24: Shell & Tube Heat Exchanger | C24: Thermosyphon - Reboiler | D24: Single Pass | E24: Pad Plates For Lifting Lug | F24: 1A10118212 | G24: Plate | H24: 1A | I24: US | J24: ASTM A240 | K24: Gr 304 | L24: 1500 | M24: mm | N24: Hot Rolled | R24: Mill Finish
A25: PDS - Shell & Tube HE | B25: Shell & Tube Heat Exchanger | C25: Thermosyphon - Reboiler | D25: Single Pass | E25: Lifting Lug | F25: 1A10113414 | G25: Plate | H25: 2A | I25: US | J25: ASTM A240 | K25: Gr 304 | L25: 1500 | M25: mm | N25: Hot Rolled | R25: Mill Finish
A26: PDS - Shell & Tube HE | B26: Shell & Tube Heat Exchanger | C26: Thermosyphon - Reboiler | D26: Single Pass | E26: Trunion Pipe | F26: 1A10313512 | G26: Pipe | H26: 3A | I26: India | J26: IS 1239 | K26: Gr A | L26: 200 | M26: NB | N26: ERW | P26: IS 1239 | Q26: Class C
A27: PDS - Shell & Tube HE | B27: Shell & Tube Heat Exchanger | C27: Thermosyphon - Reboiler | D27: Single Pass | E27: Trunion Pad Plate | F27: 1A10119912 | G27: Plate | H27: 1A | I27: US | J27: ASTM A240 | K27: Gr 304 | L27: 1500 | M27: mm | N27: Hot Rolled | R27: Mill Finish
A28: PDS - Shell & Tube HE | B28: Shell & Tube Heat Exchanger | C28: Thermosyphon - Reboiler | D28: Single Pass | E28: Cover Plate | F28: 1A10110412 | G28: Plate | H28: 1A | I28: India | J28: IS 2062 | K28: Gr A | L28: 1500 | M28: mm | N28: Hot Rolled | R28: Mill Finish
A29: PDS - Shell & Tube HE | B29: Shell & Tube Heat Exchanger | C29: Thermosyphon - Reboiler | D29: Single Pass | E29: Name Plate Bracket | F29: 1A10113112 | G29: Plate | H29: 2C | I29: US | J29: ASTM A240 | K29: Gr 304 | L29: 1500 | M29: mm | N29: Hot Rolled | R29: Mill Finish
A30: PDS - Shell & Tube HE | B30: Shell & Tube Heat Exchanger | C30: Thermosyphon - Reboiler | D30: Single Pass | E30: Setting Bolt | F30: 1A11413912 | G30: Nut, Bolt & Washer | H30: 2B | I30: India | J30: IS 1367 | K30: Gr 8.8 | L30: M20 | M30: mm | N30: Hexagonal Type
A31: PDS - Shell & Tube HE | B31: Shell & Tube Heat Exchanger | C31: Thermosyphon - Reboiler | D31: Single Pass | E31: Lifting Lug | F31: 1A10113412 | G31: Plate | H31: 2A | I31: US | J31: ASTM A240 | K31: Gr 304 | L31: 1500 | M31: mm | N31: Hot Rolled | R31: Mill Finish

Sheet Reboiler + Cooler
A1: PDS Name | B1: Equipment Category | C1: Equipment Type | D1: Equipment Subtype | E1: Location Name | F1: Indent No | G1: Item Name | H1: Priority | I1: General Standard | J1: MOC Standard | K1: MOC Grade | L1: Item Size | M1: Item Unit | N1: Item Type | O1: Item Subtype | P1: Dimensional Standard | Q1: MOC Schedule/Class | R1: Item Finish
A2: PDS - Shell & Tube HE | B2: Shell & Tube Heat Exchanger | C2: Thermosyphon - Reboiler | D2: Single Pass | E2: Shell Plate | F2: 1A10110412 | G2: Plate | H2: 1A | I2: US | J2: ASTM A240 | K2: Gr 304 | L2: 1500 | M2: mm | N2: Hot Rolled | R2: Mill Finish
A3: PDS - Shell & Tube HE | B3: Shell & Tube Heat Exchanger | C3: Thermosyphon - Reboiler | D3: Single Pass | E3: Dishend | F3: 1A10110112 | G3: Plate | H3: 1A | I3: US | J3: ASTM A240 | K3: Gr 304 | L3: 1500 | M3: mm | N3: Hot Rolled | R3: Mill Finish
A4: PDS - Shell & Tube HE | B4: Shell & Tube Heat Exchanger | C4: Thermosyphon - Reboiler | D4: Single Pass | E4: Bonnet Shell | F4: 1A10114312 | G4: Plate | H4: 3A | I4: US | J4: ASTM A240 | K4: Gr 304 | L4: 1500 | M4: mm | N4: Hot Rolled | R4: Mill Finish
A5: PDS - Shell & Tube HE | B5: Shell & Tube Heat Exchanger | C5: Thermosyphon - Reboiler | D5: Single Pass | E5: Bonnet Shell | F5: 1A10114312 | G5: Plate | H5: 3A | I5: US | J5: ASTM A240 | K5: Gr 304 | L5: 1500 | M5: mm | N5: Hot Rolled | R5: Mill Finish
A6: PDS - Shell & Tube HE | B6: Shell & Tube Heat Exchanger | C6: Thermosyphon - Reboiler | D6: Single Pass | E6: Tubes | F6: 1A12316512 | G6: Tube | H6: 1A | I6: US | J6: ASTM A249 | K6: Gr 304 | L6: 38.1 | M6: mm | N6: Circular | O6: ERW | P6: ASTM A450 | R6: Mill Finish
A7: PDS - Shell & Tube HE | B7: Shell & Tube Heat Exchanger | C7: Thermosyphon - Reboiler | D7: Single Pass | E7: Tubesheet | F7: 1A12215912 | G7: Tubesheet | H7: 1B | I7: US | J7: ASTM A240 | K7: Gr 304 | M7: mm | N7: Circular
A8: PDS - Shell & Tube HE | B8: Shell & Tube Heat Exchanger | C8: Thermosyphon - Reboiler | D8: Single Pass | E8: Baffle Plate | F8: 1A10116012 | G8: Plate | H8: 1A | I8: US | J8: ASTM A240 | K8: Gr 304 | L8: 1500 | M8: mm | N8: Hot Rolled | R8: Mill Finish
A9: PDS - Shell & Tube HE | B9: Shell & Tube Heat Exchanger | C9: Thermosyphon - Reboiler | D9: Single Pass | E9: Tie Rod | F9: 1A12516212 | G9: Solid Bar | H9: 1C | I9: US | J9: AISI 304 | L9: 14 | M9: mm | N9: Round Bar
A10: PDS - Shell & Tube HE | B10: Shell & Tube Heat Exchanger | C10: Thermosyphon - Reboiler | D10: Single Pass | E10: Spacer Tube | F10: 1A12316112 | G10: Pipe | H10: 1C | I10: US | J10: AISI 304 | L10: 15 | M10: NB | N10: ERW | P10: ASME B36.10M | Q10: Sch 5S
A11: PDS - Shell & Tube HE | B11: Shell & Tube Heat Exchanger | C11: Thermosyphon - Reboiler | D11: Single Pass | E11: Hex Nut | F11: 1A11219712 | G11: Nut, Bolt & Washer | H11: 2C | I11: US | J11: AISI 304 | L11: M14 | M11: mm | N11: Hexagonal Type
A12: PDS - Shell & Tube HE | B12: Shell & Tube Heat Exchanger | C12: Thermosyphon - Reboiler | D12: Single Pass | E12: Lock Nut | F12: 1A11216712 | G12: Nut, Bolt & Washer | H12: 2C | I12: US | J12: AISI 304 | L12: M14 | M12: mm | N12: Hexagonal Type
A13: PDS - Shell & Tube HE | B13: Shell & Tube Heat Exchanger | C13: Thermosyphon - Reboiler | D13: Single Pass | E13: Body Flange Liner | F13: 1A10110912 | G13: Plate | H13: 1A | I13: US | J13: ASTM A240 | K13: Gr 304 | L13: 1500 | M13: mm | N13: Hot Rolled | R13: Mill Finish
A14: PDS - Shell & Tube HE | B14: Shell & Tube Heat Exchanger | C14: Thermosyphon - Reboiler | D14: Single Pass | E14: Body Flange | F14: 1A10210612 | G14: Flat - Plate | H14: 1B | I14: India | J14: IS 2062 | K14: Gr B | L14: 80 | M14: mm | N14: Hot Rolled | R14: Mill Finish
A15: PDS - Shell & Tube HE | B15: Shell & Tube Heat Exchanger | C15: Thermosyphon - Reboiler | D15: Single Pass | E15: Gasket - Body Flange | F15: 1A10810812 | G15: Gasket | H15: 2C | M15: mm | N15: NACF
A16: PDS - Shell & Tube HE | B16: Shell & Tube Heat Exchanger | C16: Thermosyphon - Reboiler | D16: Single Pass | E16: Nut Bolt & Washer - Body Flange | F16: 1A11410712 | G16: Nut, Bolt & Washer | H16: 3A | I16: India | J16: IS 1367 | K16: Gr 8.8 | L16: M24 | M16: mm | N16: Hexagonal Type
A17: PDS - Shell & Tube HE | B17: Shell & Tube Heat Exchanger | C17: Thermosyphon - Reboiler | D17: Single Pass | E17: Pad Plate For Lug Support | F17: 1A10134712 | G17: Plate | H17: 2A | I17: US | J17: ASTM A240 | K17: Gr 304 | L17: 1500 | M17: mm | N17: Hot Rolled | R17: Mill Finish
A18: PDS - Shell & Tube HE | B18: Shell & Tube Heat Exchanger | C18: Thermosyphon - Reboiler | D18: Single Pass | E18: Gusset Plate | F18: 1A10112912 | G18: Plate | H18: 2A | I18: India | J18: IS 2062 | K18: Gr A | L18: 1500 | M18: mm | N18: Hot Rolled | R18: Mill Finish
A19: PDS - Shell & Tube HE | B19: Shell & Tube Heat Exchanger | C19: Thermosyphon - Reboiler | D19: Single Pass | E19: Base Plate | F19: 1A10112812 | G19: Plate | H19: 1B | I19: India | J19: IS 2062 | K19: Gr A | L19: 1500 | M19: mm | N19: Hot Rolled | R19: Mill Finish
A20: PDS - Shell & Tube HE | B20: Shell & Tube Heat Exchanger | C20: Thermosyphon - Reboiler | D20: Single Pass | E20: Earthing Boss | F20: 1A12913712 | G20: Earthing Boss | H20: 3C | I20: India | J20: IS 2062 | K20: Gr A | L20: 40 x 40 x M12 | M20: mm
A21: PDS - Shell & Tube HE | B21: Shell & Tube Heat Exchanger | C21: Thermosyphon - Reboiler | D21: Single Pass | E21: Pad Plates For Lifting Lug | F21: 1A10118212 | G21: Plate | H21: 1A | I21: US | J21: ASTM A240 | K21: Gr 304 | L21: 1500 | M21: mm | N21: Hot Rolled | R21: Mill Finish
A22: PDS - Shell & Tube HE | B22: Shell & Tube Heat Exchanger | C22: Thermosyphon - Reboiler | D22: Single Pass | E22: Lifting Lug | F22: 1A10113414 | G22: Plate | H22: 2A | I22: US | J22: ASTM A240 | K22: Gr 304 | L22: 1500 | M22: mm | N22: Hot Rolled | R22: Mill Finish
A23: PDS - Shell & Tube HE | B23: Shell & Tube Heat Exchanger | C23: Thermosyphon - Reboiler | D23: Single Pass | E23: Trunion Pipe | F23: 1A10313512 | G23: Pipe | H23: 3A | I23: India | J23: IS 1239 | K23: Gr A | L23: 200 | M23: NB | N23: ERW | P23: IS 1239 | Q23: Class C
A24: PDS - Shell & Tube HE | B24: Shell & Tube Heat Exchanger | C24: Thermosyphon - Reboiler | D24: Single Pass | E24: Trunion Pad Plate | F24: 1A10119912 | G24: Plate | H24: 1A | I24: US | J24: ASTM A240 | K24: Gr 304 | L24: 1500 | M24: mm | N24: Hot Rolled | R24: Mill Finish
A25: PDS - Shell & Tube HE | B25: Shell & Tube Heat Exchanger | C25: Thermosyphon - Reboiler | D25: Single Pass | E25: Cover Plate | F25: 1A10110412 | G25: Plate | H25: 1A | I25: India | J25: IS 2062 | K25: Gr A | L25: 1500 | M25: mm | N25: Hot Rolled | R25: Mill Finish
A26: PDS - Shell & Tube HE | B26: Shell & Tube Heat Exchanger | C26: Thermosyphon - Reboiler | D26: Single Pass | E26: Name Plate Bracket | F26: 1A10113112 | G26: Plate | H26: 2C | I26: US | J26: ASTM A240 | K26: Gr 304 | L26: 1500 | M26: mm | N26: Hot Rolled | R26: Mill Finish
A27: PDS - Shell & Tube HE | B27: Shell & Tube Heat Exchanger | C27: Thermosyphon - Reboiler | D27: Single Pass | E27: Setting Bolt | F27: 1A11413912 | G27: Nut, Bolt & Washer | H27: 2B | I27: India | J27: IS 1367 | K27: Gr 8.8 | L27: M20 | M27: mm | N27: Hexagonal Type

Sheet Super-Heater
A1: PDS Name | B1: Equipment Category | C1: Equipment Type | D1: Equipment Subtype | E1: Location Name | F1: Indent No | G1: Item Name | H1: Priority | I1: General Standard | J1: MOC Standard | K1: MOC Grade | L1: Item Size | M1: Item Unit | N1: Item Type | O1: Item Subtype | P1: Dimensional Standard | Q1: MOC Schedule/Class | R1: Item Finish
A2: PDS - Shell & Tube HE | B2: Shell & Tube Heat Exchanger | C2: Superheater | D2: Single Pass | E2: Shell Plate | F2: 1A10110412 | G2: Plate | H2: 1A | I2: US | J2: ASTM A240 | K2: Gr 304 | L2: 1500 | M2: mm | N2: Hot Rolled | R2: Mill Finish
A3: PDS - Shell & Tube HE | B3: Shell & Tube Heat Exchanger | C3: Superheater | D3: Single Pass | E3: Cone | F3: 1A10110212 | G3: Plate | H3: 1A | I3: US | J3: ASTM A240 | K3: Gr 304 | L3: 1500 | M3: mm | N3: Hot Rolled | R3: Mill Finish
A4: PDS - Shell & Tube HE | B4: Shell & Tube Heat Exchanger | C4: Superheater | D4: Single Pass | E4: Bonnet Shell | F4: 1A10114312 | G4: Plate | H4: 3A | I4: US | J4: ASTM A240 | K4: Gr 304 | L4: 1500 | M4: mm | N4: Hot Rolled | R4: Mill Finish
A5: PDS - Shell & Tube HE | B5: Shell & Tube Heat Exchanger | C5: Superheater | D5: Single Pass | E5: Bonnet Shell | F5: 1A10114312 | G5: Plate | H5: 3A | I5: US | J5: ASTM A240 | K5: Gr 304 | L5: 1500 | M5: mm | N5: Hot Rolled | R5: Mill Finish
A6: PDS - Shell & Tube HE | B6: Shell & Tube Heat Exchanger | C6: Superheater | D6: Single Pass | E6: Tubes | F6: 1A12316512 | G6: Tube | H6: 1A | I6: US | J6: ASTM A249 | K6: Gr 304 | L6: 19.05 | M6: mm | N6: Circular | O6: ERW | P6: ASTM A450 | R6: Mill Finish
A7: PDS - Shell & Tube HE | B7: Shell & Tube Heat Exchanger | C7: Superheater | D7: Single Pass | E7: Tubesheet | F7: 1A12215912 | G7: Tubesheet | H7: 1B | I7: US | J7: ASTM A240 | K7: Gr 304 | M7: mm | N7: Circular
A8: PDS - Shell & Tube HE | B8: Shell & Tube Heat Exchanger | C8: Superheater | D8: Single Pass | E8: Baffle Plate | F8: 1A10116012 | G8: Plate | H8: 1A | I8: US | J8: ASTM A240 | K8: Gr 304 | L8: 1500 | M8: mm | N8: Hot Rolled | R8: Mill Finish
A9: PDS - Shell & Tube HE | B9: Shell & Tube Heat Exchanger | C9: Superheater | D9: Single Pass | E9: Tie Rod | F9: 1A12516212 | G9: Solid Bar | H9: 1C | I9: US | J9: AISI 304 | L9: 14 | M9: mm | N9: Round Bar
A10: PDS - Shell & Tube HE | B10: Shell & Tube Heat Exchanger | C10: Superheater | D10: Single Pass | E10: Spacer Tube | F10: 1A12316112 | G10: Pipe | H10: 1C | I10: US | J10: AISI 304 | L10: 15 | M10: NB | N10: ERW | P10: ASME B36.10M | Q10: Sch 5S
A11: PDS - Shell & Tube HE | B11: Shell & Tube Heat Exchanger | C11: Superheater | D11: Single Pass | E11: Hex Nut | F11: 1A11219712 | G11: Nut, Bolt & Washer | H11: 2C | I11: US | J11: AISI 304 | L11: M14 | M11: mm | N11: Hexagonal Type
A12: PDS - Shell & Tube HE | B12: Shell & Tube Heat Exchanger | C12: Superheater | D12: Single Pass | E12: Lock Nut | F12: 1A11216712 | G12: Nut, Bolt & Washer | H12: 2C | I12: US | J12: AISI 304 | L12: M14 | M12: mm | N12: Hexagonal Type
A13: PDS - Shell & Tube HE | B13: Shell & Tube Heat Exchanger | C13: Superheater | D13: Single Pass | E13: Body Flange Liner | F13: 1A10110912 | G13: Plate | H13: 1A | I13: US | J13: ASTM A240 | K13: Gr 304 | L13: 1500 | M13: mm | N13: Hot Rolled | R13: Mill Finish
A14: PDS - Shell & Tube HE | B14: Shell & Tube Heat Exchanger | C14: Superheater | D14: Single Pass | E14: Body Flange | F14: 1A10210612 | G14: Flat - Plate | H14: 1B | I14: India | J14: IS 2062 | K14: Gr B | L14: 80 | M14: mm | N14: Hot Rolled | R14: Mill Finish
A15: PDS - Shell & Tube HE | B15: Shell & Tube Heat Exchanger | C15: Superheater | D15: Single Pass | E15: Gasket - Body Flange | F15: 1A10810812 | G15: Gasket | H15: 2C | M15: mm | N15: NACF
A16: PDS - Shell & Tube HE | B16: Shell & Tube Heat Exchanger | C16: Superheater | D16: Single Pass | E16: Nut Bolt & Washer - Body Flange | F16: 1A11410712 | G16: Nut, Bolt & Washer | H16: 3A | I16: India | J16: IS 1367 | K16: Gr 8.8 | L16: M24 | M16: mm | N16: Hexagonal Type
A17: PDS - Shell & Tube HE | B17: Shell & Tube Heat Exchanger | C17: Superheater | D17: Single Pass | E17: Pad Plate For Lug Support | F17: 1A10134712 | G17: Plate | H17: 2A | I17: US | J17: ASTM A240 | K17: Gr 304 | L17: 1500 | M17: mm | N17: Hot Rolled | R17: Mill Finish
A18: PDS - Shell & Tube HE | B18: Shell & Tube Heat Exchanger | C18: Superheater | D18: Single Pass | E18: Gusset Plate | F18: 1A10112912 | G18: Plate | H18: 2A | I18: India | J18: IS 2062 | K18: Gr A | L18: 1500 | M18: mm | N18: Hot Rolled | R18: Mill Finish
A19: PDS - Shell & Tube HE | B19: Shell & Tube Heat Exchanger | C19: Superheater | D19: Single Pass | E19: Base Plate | F19: 1A10112812 | G19: Plate | H19: 1B | I19: India | J19: IS 2062 | K19: Gr A | L19: 1500 | M19: mm | N19: Hot Rolled | R19: Mill Finish
A20: PDS - Shell & Tube HE | B20: Shell & Tube Heat Exchanger | C20: Superheater | D20: Single Pass | E20: Earthing Boss | F20: 1A12913712 | G20: Earthing Boss | H20: 3C | I20: India | J20: IS 2062 | K20: Gr A | L20: 40 x 40 x M12 | M20: mm
A21: PDS - Shell & Tube HE | B21: Shell & Tube Heat Exchanger | C21: Superheater | D21: Single Pass | E21: Name Plate Bracket | F21: 1A10113112 | G21: Plate | H21: 2C | I21: US | J21: ASTM A240 | K21: Gr 304 | L21: 1500 | M21: mm | N21: Hot Rolled | R21: Mill Finish
A22: PDS - Shell & Tube HE | B22: Shell & Tube Heat Exchanger | C22: Superheater | D22: Single Pass | E22: Pad Plates For Lifting Lug | F22: 1A10118212 | G22: Plate | H22: 1A | I22: US | J22: ASTM A240 | K22: Gr 304 | L22: 1500 | M22: mm | N22: Hot Rolled | R22: Mill Finish
A23: PDS - Shell & Tube HE | B23: Shell & Tube Heat Exchanger | C23: Superheater | D23: Single Pass | E23: Lifting Lug | F23: 1A10113414 | G23: Plate | H23: 2A | I23: US | J23: ASTM A240 | K23: Gr 304 | L23: 1500 | M23: mm | N23: Hot Rolled | R23: Mill Finish
A24: PDS - Shell & Tube HE | B24: Shell & Tube Heat Exchanger | C24: Superheater | D24: Single Pass | E24: Setting Bolt | F24: 1A11413912 | G24: Nut, Bolt & Washer | H24: 2B | I24: India | J24: IS 1367 | K24: Gr 8.8 | L24: M20 | M24: mm | N24: Hexagonal Type
A25: PDS - Shell & Tube HE | B25: Shell & Tube Heat Exchanger | C25: Superheater | D25: Single Pass | E25: Plate For Bellow Shell
A26: PDS - Shell & Tube HE | B26: Shell & Tube Heat Exchanger | C26: Superheater | D26: Single Pass | E26: Strip For Bellow
A27: PDS - Shell & Tube HE | B27: Shell & Tube Heat Exchanger | C27: Superheater | D27: Single Pass | E27: Plate for Bellow

Sheet Forced Evaporator 
A1: PDS Name | B1: Equipment Category | C1: Equipment Type | D1: Equipment Subtype | E1: Location Name | F1: Indent No | G1: Item Name | H1: Priority | I1: General Standard | J1: MOC Standard | K1: MOC Grade | L1: Item Size | M1: Item Unit | N1: Item Type | O1: Item Subtype | P1: Dimensional Standard | Q1: MOC Schedule/Class | R1: Item Finish
A2: PDS - Shell & Tube HE | B2: Shell & Tube Heat Exchanger | C2: Forced Circulation Evaporator | D2: Four Pass | E2: Shell Plate | F2: 1A10110412 | G2: Plate | H2: 1A | I2: US | J2: ASTM A240 | K2: Gr 304 | L2: 1500 | M2: mm | N2: Hot Rolled | R2: Mill Finish
A3: PDS - Shell & Tube HE | B3: Shell & Tube Heat Exchanger | C3: Forced Circulation Evaporator | D3: Four Pass | E3: Blind Flange | F3: 1A10621912 | G3: Plate | H3: 2C | I3: India | J3: IS 2062 | K3: Gr B | M3: mm | N3: Hot Rolled | R3: Mill Finish
A4: PDS - Shell & Tube HE | B4: Shell & Tube Heat Exchanger | C4: Forced Circulation Evaporator | D4: Four Pass | E4: Bonnet Shell | F4: 1A10114312 | G4: Plate | H4: 3A | I4: US | J4: ASTM A240 | K4: Gr 304 | L4: 1500 | M4: mm | N4: Hot Rolled | R4: Mill Finish
A5: PDS - Shell & Tube HE | B5: Shell & Tube Heat Exchanger | C5: Forced Circulation Evaporator | D5: Four Pass | E5: Bonnet Shell | F5: 1A10114312 | G5: Plate | H5: 3A | I5: US | J5: ASTM A240 | K5: Gr 304 | L5: 1500 | M5: mm | N5: Hot Rolled | R5: Mill Finish
A6: PDS - Shell & Tube HE | B6: Shell & Tube Heat Exchanger | C6: Forced Circulation Evaporator | D6: Four Pass | E6: Blind Flange Liner | F6: 1A10118612 | G6: Plate | H6: 1A | I6: US | J6: ASTM A240 | K6: Gr 304 | L6: 1500 | M6: mm | N6: Hot Rolled | R6: Mill Finish
A7: PDS - Shell & Tube HE | B7: Shell & Tube Heat Exchanger | C7: Forced Circulation Evaporator | D7: Four Pass | E7: Body Flange Flat | F7: 1A10210612 | G7: Flat - Plate | H7: 1B | I7: India | J7: IS 2062 | K7: Gr B | L7: 75 | M7: mm | N7: Hot Rolled | R7: Mill Finish
A8: PDS - Shell & Tube HE | B8: Shell & Tube Heat Exchanger | C8: Forced Circulation Evaporator | D8: Four Pass | E8: Body Flange Liner | F8: 1A10110912 | G8: Plate | H8: 1A | I8: US | J8: ASTM A240 | K8: Gr 304 | L8: 1500 | M8: mm | N8: Hot Rolled | R8: Mill Finish
A9: PDS - Shell & Tube HE | B9: Shell & Tube Heat Exchanger | C9: Forced Circulation Evaporator | D9: Four Pass | E9: Gasket - Body Flange | F9: 1A10810812 | G9: Gasket | H9: 2C | M9: mm | N9: NACF
A10: PDS - Shell & Tube HE | B10: Shell & Tube Heat Exchanger | C10: Forced Circulation Evaporator | D10: Four Pass | E10: Tubesheet | F10: 1A12215912 | G10: Tubesheet | H10: 1B | I10: US | J10: ASTM A240 | K10: Gr 304 | M10: mm | N10: Circular
A11: PDS - Shell & Tube HE | B11: Shell & Tube Heat Exchanger | C11: Forced Circulation Evaporator | D11: Four Pass | E11: Nut Bolt & Washer - Body Flange | F11: 1A11410712 | G11: Nut, Bolt & Washer | H11: 3A | I11: India | J11: IS 1367 | K11: Gr 8.8 | L11: M20 | M11: mm | N11: Hexagonal Type
A12: PDS - Shell & Tube HE | B12: Shell & Tube Heat Exchanger | C12: Forced Circulation Evaporator | D12: Four Pass | E12: Tubes | F12: 1A12316512 | G12: Tube | H12: 1A | I12: US | J12: ASTM A249 | K12: Gr 316L | L12: 38.1 | M12: mm | N12: Circular | O12: ERW | R12: Mill Finish
A13: PDS - Shell & Tube HE | B13: Shell & Tube Heat Exchanger | C13: Forced Circulation Evaporator | D13: Four Pass | E13: Baffle Plate | F13: 1A10116012 | G13: Plate | H13: 1A | I13: US | J13: ASTM A240 | K13: Gr 304 | L13: 1500 | M13: mm | N13: Hot Rolled | R13: Mill Finish
A14: PDS - Shell & Tube HE | B14: Shell & Tube Heat Exchanger | C14: Forced Circulation Evaporator | D14: Four Pass | E14: Tie Rod | F14: 1A12516212 | G14: Solid Bar | H14: 1C | I14: US | J14: AISI 304 | L14: 12 | M14: mm | N14: Round Bar
A15: PDS - Shell & Tube HE | B15: Shell & Tube Heat Exchanger | C15: Forced Circulation Evaporator | D15: Four Pass | E15: Spacer Tube | F15: 1A12316112 | G15: Pipe | H15: 1C | I15: US | J15: AISI 304 | L15: 10 | M15: NB | N15: ERW | P15: ASME B36.10M | Q15: Sch 5S
A16: PDS - Shell & Tube HE | B16: Shell & Tube Heat Exchanger | C16: Forced Circulation Evaporator | D16: Four Pass | E16: Hex Nut | F16: 1A11219712 | G16: Nut | H16: 2C | I16: US | J16: AISI 304 | L16: M12 | M16: mm | N16: Hex Nut
E17: Lock Nut | F17: 1A11216712 | G17: Nut | H17: 2C | I17: US | J17: AISI 304 | L17: M12 | M17: mm | N17: Hex Nut
A18: PDS - Shell & Tube HE | B18: Shell & Tube Heat Exchanger | C18: Forced Circulation Evaporator | D18: Four Pass | E18: Trunion Pad Plate | F18: 1A10119912 | G18: Plate | H18: 1A | I18: US | J18: ASTM A240 | K18: Gr 304 | L18: 1500 | M18: mm | N18: Hot Rolled | R18: Mill Finish
A19: PDS - Shell & Tube HE | B19: Shell & Tube Heat Exchanger | C19: Forced Circulation Evaporator | D19: Four Pass | E19: Trunion Pipe | F19: 1A10313512 | G19: Pipe | H19: 3A | I19: India | J19: IS 1239 | K19: Part I | L19: 150 | M19: NB | N19: ERW | P19: IS 1239 | Q19: Class C
A20: PDS - Shell & Tube HE | B20: Shell & Tube Heat Exchanger | C20: Forced Circulation Evaporator | D20: Four Pass | E20: Trunion Closer Plate | F20: 1A10113612 | G20: Plate | H20: 1B | I20: India | J20: IS 2062 | K20: Gr A | L20: 1500 | M20: mm | N20: Hot Rolled | R20: Mill Finish
A21: PDS - Shell & Tube HE | B21: Shell & Tube Heat Exchanger | C21: Forced Circulation Evaporator | D21: Four Pass | E21: Name Plate Bracket | F21: 1A10113112 | G21: Plate | H21: 2C | I21: US | J21: ASTM A240 | K21: Gr 304 | L21: 1500 | M21: mm | N21: Hot Rolled | R21: Mill Finish
A22: PDS - Shell & Tube HE | B22: Shell & Tube Heat Exchanger | C22: Forced Circulation Evaporator | D22: Four Pass | E22: Pad Plates For Lifting Lug | F22: 1A10118212 | G22: Plate | H22: 1A | I22: US | J22: ASTM A240 | K22: Gr 304 | L22: 1500 | M22: mm | N22: Hot Rolled | R22: Mill Finish
A23: PDS - Shell & Tube HE | B23: Shell & Tube Heat Exchanger | C23: Forced Circulation Evaporator | D23: Four Pass | E23: Lifting Lug | F23: 1A10113412 | G23: Plate | H23: 2A | I23: India | J23: IS 2062 | K23: Gr A | L23: 1500 | M23: mm | N23: Hot Rolled | R23: Mill Finish
A24: PDS - Shell & Tube HE | B24: Shell & Tube Heat Exchanger | C24: Forced Circulation Evaporator | D24: Four Pass | E24: Earthing Boss | F24: 1A12913712 | G24: Earthing Boss | H24: 3C | I24: India | J24: IS 2062 | L24: 40 x 40 x M12 | M24: mm
A25: PDS - Shell & Tube HE | B25: Shell & Tube Heat Exchanger | C25: Forced Circulation Evaporator | D25: Four Pass | E25: External Stiffner | F25: 1A10210312 | G25: Flat - Plate | H25: 1B | I25: US | J25: ASTM A240 | K25: Gr 304 | L25: 50 | M25: mm | N25: Hot Rolled | R25: Mill Finish
A26: PDS - Shell & Tube HE | B26: Shell & Tube Heat Exchanger | C26: Forced Circulation Evaporator | D26: Four Pass | E26: Partition Plate | F26: 1A10117112 | G26: Plate | H26: 1A | I26: US | J26: ASTM A240 | K26: Gr 304 | L26: 1500 | M26: mm | N26: Hot Rolled | R26: Mill Finish
A27: PDS - Shell & Tube HE | B27: Shell & Tube Heat Exchanger | C27: Forced Circulation Evaporator | D27: Four Pass | E27: Partition Plate | F27: 1A10117112 | G27: Plate | H27: 1A | I27: US | J27: ASTM A240 | K27: Gr 304 | L27: 1500 | M27: mm | N27: Hot Rolled | R27: Mill Finish
A28: PDS - Shell & Tube HE | B28: Shell & Tube Heat Exchanger | C28: Forced Circulation Evaporator | D28: Four Pass | E28: Partition Plate | F28: 1A10117112 | G28: Plate | H28: 1A | I28: US | J28: ASTM A240 | K28: Gr 304 | L28: 1500 | M28: mm | N28: Hot Rolled | R28: Mill Finish
A29: PDS - Shell & Tube HE | B29: Shell & Tube Heat Exchanger | C29: Forced Circulation Evaporator | D29: Four Pass | E29: C - Type Gasket | F29: 1A10819312 | G29: Gasket | H29: 2C | M29: mm | N29: NACF
A30: PDS - Shell & Tube HE | B30: Shell & Tube Heat Exchanger | C30: Forced Circulation Evaporator | D30: Four Pass | E30: Lifting Lug | F30: 1A10113412 | G30: Plate | H30: 2A | I30: India | J30: IS 2062 | K30: Gr A | L30: 1500 | M30: mm | N30: Hot Rolled | R30: Mill Finish
A31: PDS - Shell & Tube HE | B31: Shell & Tube Heat Exchanger | C31: Forced Circulation Evaporator | D31: Four Pass | E31: Lifting Lug | F31: 1A10113412 | G31: Plate | H31: 2A | I31: US | J31: ASTM A240 | K31: Gr 304 | L31: 1500 | M31: mm | N31: Hot Rolled | R31: Mill Finish
A32: PDS - Shell & Tube HE | B32: Shell & Tube Heat Exchanger | C32: Forced Circulation Evaporator | D32: Four Pass | E32: Pad Plate For Support Ring | F32: 1A10134812 | G32: Plate | H32: 2A | I32: US | J32: ASTM A240 | K32: Gr 304 | L32: 1500 | M32: mm | N32: Hot Rolled | R32: Mill Finish
A33: PDS - Shell & Tube HE | B33: Shell & Tube Heat Exchanger | C33: Forced Circulation Evaporator | D33: Four Pass | E33: Gusset Plate | F33: 1A10112912 | G33: Plate | H33: 2A | I33: US | J33: ASTM A240 | K33: Gr 304 | L33: 1500 | M33: mm | N33: Hot Rolled | R33: Mill Finish
A34: PDS - Shell & Tube HE | B34: Shell & Tube Heat Exchanger | C34: Forced Circulation Evaporator | D34: Four Pass | E34: Top Support Ring | F34: 1A10120612 | G34: Plate | H34: 2A | I34: India | J34: IS 2062 | K34: Gr A | L34: 1500 | M34: mm | N34: Hot Rolled | R34: Mill Finish
A35: PDS - Shell & Tube HE | B35: Shell & Tube Heat Exchanger | C35: Forced Circulation Evaporator | D35: Four Pass | E35: Bottom Support Ring | F35: 1A10120712 | G35: Plate | H35: 2A | I35: India | J35: IS 2062 | K35: Gr A | L35: 1500 | M35: mm | N35: Hot Rolled | R35: Mill Finish
A36: PDS - Shell & Tube HE | B36: Shell & Tube Heat Exchanger | C36: Forced Circulation Evaporator | D36: Four Pass | E36: Setting Bolt | F36: 1A11413912 | G36: Nut, Bolt & Washer | H36: 2B | I36: India | J36: IS 1367 | K36: Gr 8.8 | L36: M24 | M36: mm | N36: Hexagonal Type

Sheet FF Evaporator
A1: PDS Name | B1: Equipment Category | C1: Equipment Type | D1: Equipment Subtype | E1: Location Name | F1: Indent No | G1: Item Name | H1: Priority | I1: General Standard | J1: MOC Standard | K1: MOC Grade | L1: Item Size | M1: Item Unit | N1: Item Type | O1: Item Subtype | P1: Dimensional Standard | Q1: MOC Schedule/Class | R1: Item Finish
A2: PDS - Shell & Tube HE | B2: Shell & Tube Heat Exchanger | C2: Falling Film Evaporator | D2: Single Pass | E2: Shell Plate | F2: 1A10110412 | G2: Plate | H2: 1A | I2: US | J2: ASTM A240 | K2: Gr 304 | L2: 1500 | M2: mm | N2: Hot Rolled | R2: Mill Finish
